<?xml version="1.0" encoding="UTF-8"?>
<robot name="LBR3R760iisy">
  <joint name="LBR3R760iisy_BaseJoint" type="fixed">
    <child link="LBR3R760iisy_FixedBase"/>
    <parent link="base_link"/>
  </joint>
  <joint name="Joint5" type="revolute">
    <axis xyz="0.0 0.0 1.0"/>
    <child link="LBR3R760iisy_Link5"/>
    <limit effort="5.0E2" lower="-1.919862177E0" upper="1.919862177E0" velocity="2.0E0"/>
    <origin rpy="-1.5707963267948963 0.0 -0.0" xyz="0.0 0.0 -0.3"/>
    <parent link="LBR3R760iisy_Link4"/>
  </joint>
  <joint name="Joint3" type="revolute">
    <axis xyz="0.0 0.0 1.0"/>
    <child link="LBR3R760iisy_Link3"/>
    <limit effort="5.0E2" lower="-2.61799387799E0" upper="2.61799387799E0" velocity="2.0E0"/>
    <origin rpy="0.0 0.0 -1.5707963267948963" xyz="0.3 0.0 0.0"/>
    <parent link="LBR3R760iisy_Link2"/>
  </joint>
  <joint name="Joint6" type="revolute">
    <axis xyz="0.0 0.0 1.0"/>
    <child link="LBR3R760iisy_Link6"/>
    <limit effort="5.0E2" lower="-3.839724354E0" upper="3.839724354E0" velocity="2.0E0"/>
    <origin rpy="1.5707963267948963 0.0 -0.0" xyz="0.0 0.0 0.0"/>
    <parent link="LBR3R760iisy_Link5"/>
  </joint>
  <joint name="Joint1" type="revolute">
    <axis xyz="0.0 0.0 -1.0"/>
    <child link="LBR3R760iisy_Link1"/>
    <limit effort="5.0E2" lower="-3.2288591E0" upper="3.2288591E0" velocity="2.0E0"/>
    <origin rpy="-0.0 0.0 -0.0" xyz="0.0 0.0 0.1264"/>
    <parent link="LBR3R760iisy_FixedBase"/>
  </joint>
  <joint name="Joint4" type="revolute">
    <axis xyz="0.0 0.0 1.0"/>
    <child link="LBR3R760iisy_Link4"/>
    <limit effort="5.0E2" lower="-3.05432619E0" upper="3.05432619E0" velocity="2.0E0"/>
    <origin rpy="1.5707963267948963 0.0 -0.0" xyz="0.0 0.0 0.0"/>
    <parent link="LBR3R760iisy_Link3"/>
  </joint>
  <joint name="Joint2" type="revolute">
    <axis xyz="0.0 0.0 1.0"/>
    <child link="LBR3R760iisy_Link2"/>
    <limit effort="5.0E2" lower="-4.0142572796E0" upper="8.726646E-1" velocity="2.0E0"/>
    <origin rpy="-1.5707963267948963 0.0 -0.0" xyz="0.0 0.0 0.0886"/>
    <parent link="LBR3R760iisy_Link1"/>
  </joint>
  <link name="LBR3R760iisy_Link1">
    <collision>
      <geometry>
        <mesh filename="LBR3R760iisy/mesh/link1.stl"/>
      </geometry>
      <origin rpy="-0.0 0.0 -0.0" xyz="0.0 0.0 0.0"/>
    </collision>
    <inertial>
      <inertia ixx="0.00864540353780418" ixy="0.0" ixz="0.0" iyy="0.00573103463618732" iyz="0.0" izz="0.00974792600424334"/>
      <mass value="3.2492E0"/>
      <origin rpy="-0.0 0.0 -0.0" xyz="0.0 0.0 0.0"/>
    </inertial>
    <visual>
      <geometry>
        <mesh filename="LBR3R760iisy/mesh/link1.stl"/>
      </geometry>
      <origin rpy="-0.0 0.0 -0.0" xyz="0.0 0.0 0.0"/>
    </visual>
  </link>
  <link name="LBR3R760iisy_Link4">
    <collision>
      <geometry>
        <mesh filename="LBR3R760iisy/mesh/link4.stl"/>
      </geometry>
      <origin rpy="-0.0 0.0 -0.0" xyz="0.0 0.0 0.0"/>
    </collision>
    <inertial>
      <inertia ixx="0.00244684891934666" ixy="0.0" ixz="0.0" iyy="0.00929300990970133" iyz="0.0" izz="0.00957902612033654"/>
      <mass value="2.0138E0"/>
      <origin rpy="-0.0 0.0 -0.0" xyz="0.0 0.0 0.0"/>
    </inertial>
    <visual>
      <geometry>
        <mesh filename="LBR3R760iisy/mesh/link4.stl"/>
      </geometry>
      <origin rpy="-0.0 0.0 -0.0" xyz="0.0 0.0 0.0"/>
    </visual>
  </link>
  <link name="LBR3R760iisy_FixedBase">
    <collision>
      <geometry>
        <mesh filename="LBR3R760iisy/mesh/robotBase.stl"/>
      </geometry>
      <origin rpy="-0.0 0.0 -0.0" xyz="0.0 0.0 0.0"/>
    </collision>
    <inertial>
      <inertia ixx="5.0E-4" ixy="0.0" ixz="0.0" iyy="5.0E-4" iyz="0.0" izz="5.0E-4"/>
      <mass value="3.6832E0"/>
      <origin rpy="-0.0 0.0 -0.0" xyz="0.0 0.0 0.0"/>
    </inertial>
    <visual>
      <geometry>
        <mesh filename="LBR3R760iisy/mesh/robotBase.stl"/>
      </geometry>
      <origin rpy="-0.0 0.0 -0.0" xyz="0.0 0.0 0.0"/>
    </visual>
  </link>
  <link name="LBR3R760iisy_Link2">
    <collision>
      <geometry>
        <mesh filename="LBR3R760iisy/mesh/link2.stl"/>
      </geometry>
      <origin rpy="-0.0 0.0 -0.0" xyz="0.0 0.0 0.0"/>
    </collision>
    <inertial>
      <inertia ixx="0.0521692170047944" ixy="0.0" ixz="0.0" iyy="0.0042331111850977" iyz="0.0" izz="0.0534425693052013"/>
      <mass value="3.212E0"/>
      <origin rpy="-0.0 0.0 -0.0" xyz="0.0 0.0 0.0"/>
    </inertial>
    <visual>
      <geometry>
        <mesh filename="LBR3R760iisy/mesh/link2.stl"/>
      </geometry>
      <origin rpy="-0.0 0.0 -0.0" xyz="0.0 0.0 0.0"/>
    </visual>
  </link>
  <link name="LBR3R760iisy_Link5">
    <collision>
      <geometry>
        <mesh filename="LBR3R760iisy/mesh/link5.stl"/>
      </geometry>
      <origin rpy="-0.0 0.0 -0.0" xyz="0.0 0.0 0.0"/>
    </collision>
    <inertial>
      <inertia ixx="0.00236252846105637" ixy="0.0" ixz="0.0" iyy="0.00141854396142661" iyz="0.0" izz="0.0025813096143987"/>
      <mass value="1.4418E0"/>
      <origin rpy="-0.0 0.0 -0.0" xyz="0.0 0.0 0.0"/>
    </inertial>
    <visual>
      <geometry>
        <mesh filename="LBR3R760iisy/mesh/link5.stl"/>
      </geometry>
      <origin rpy="-0.0 0.0 -0.0" xyz="0.0 0.0 0.0"/>
    </visual>
  </link>
  <link name="LBR3R760iisy_Link3">
    <collision>
      <geometry>
        <mesh filename="LBR3R760iisy/mesh/link3.stl"/>
      </geometry>
      <origin rpy="-0.0 0.0 -0.0" xyz="0.0 0.0 0.0"/>
    </collision>
    <inertial>
      <inertia ixx="0.0113804888378926" ixy="0.0" ixz="0.0" iyy="0.00566536942404497" iyz="0.0" izz="0.0133950588482047"/>
      <mass value="3.471E0"/>
      <origin rpy="-0.0 0.0 -0.0" xyz="0.0 0.0 0.0"/>
    </inertial>
    <visual>
      <geometry>
        <mesh filename="LBR3R760iisy/mesh/link3.stl"/>
      </geometry>
      <origin rpy="-0.0 0.0 -0.0" xyz="0.0 0.0 0.0"/>
    </visual>
  </link>
  <link name="LBR3R760iisy_Link6">
    <collision>
      <geometry>
        <mesh filename="LBR3R760iisy/mesh/link6.stl"/>
      </geometry>
      <origin rpy="-0.0 0.0 -0.0" xyz="0.0 0.0 0.0"/>
    </collision>
    <inertial>
      <inertia ixx="0.0014673917002994" ixy="0.0" ixz="0.0" iyy="0.00112131520678352" iyz="0.0" izz="0.00158160486913488"/>
      <mass value="8.43E-1"/>
      <origin rpy="-0.0 0.0 -0.0" xyz="0.0 0.0 0.0"/>
    </inertial>
    <visual>
      <geometry>
        <mesh filename="LBR3R760iisy/mesh/link6.stl"/>
      </geometry>
      <origin rpy="-0.0 0.0 -0.0" xyz="0.0 0.0 0.0"/>
    </visual>
  </link>
  <transmission name="trans_LBR3R760iisy_Urdf_Joint2_name">
    <actuator name="LBR3R760iisy_Urdf_Joint2_name_motor">
      <hardwareInterface>EffortJointInterface</hardwareInterface>
      <mechanicalReduction>1.0</mechanicalReduction>
    </actuator>
    <joint name="Joint2">
      <hardwareInterface>hardware_interface/EffortJointInterface</hardwareInterface>
    </joint>
    <type>transmission_interface/SimpleTransmission</type>
  </transmission>
  <transmission name="trans_LBR3R760iisy_Urdf_Joint5_name">
    <actuator name="LBR3R760iisy_Urdf_Joint5_name_motor">
      <hardwareInterface>EffortJointInterface</hardwareInterface>
      <mechanicalReduction>1.0</mechanicalReduction>
    </actuator>
    <joint name="Joint5">
      <hardwareInterface>hardware_interface/EffortJointInterface</hardwareInterface>
    </joint>
    <type>transmission_interface/SimpleTransmission</type>
  </transmission>
  <transmission name="trans_LBR3R760iisy_Urdf_Joint6_name">
    <actuator name="LBR3R760iisy_Urdf_Joint6_name_motor">
      <hardwareInterface>EffortJointInterface</hardwareInterface>
      <mechanicalReduction>1.0</mechanicalReduction>
    </actuator>
    <joint name="Joint6">
      <hardwareInterface>hardware_interface/EffortJointInterface</hardwareInterface>
    </joint>
    <type>transmission_interface/SimpleTransmission</type>
  </transmission>
  <transmission name="trans_LBR3R760iisy_Urdf_Joint4_name">
    <actuator name="LBR3R760iisy_Urdf_Joint4_name_motor">
      <hardwareInterface>EffortJointInterface</hardwareInterface>
      <mechanicalReduction>1.0</mechanicalReduction>
    </actuator>
    <joint name="Joint4">
      <hardwareInterface>hardware_interface/EffortJointInterface</hardwareInterface>
    </joint>
    <type>transmission_interface/SimpleTransmission</type>
  </transmission>
  <transmission name="trans_LBR3R760iisy_Urdf_Joint3_name">
    <actuator name="LBR3R760iisy_Urdf_Joint3_name_motor">
      <hardwareInterface>EffortJointInterface</hardwareInterface>
      <mechanicalReduction>1.0</mechanicalReduction>
    </actuator>
    <joint name="Joint3">
      <hardwareInterface>hardware_interface/EffortJointInterface</hardwareInterface>
    </joint>
    <type>transmission_interface/SimpleTransmission</type>
  </transmission>
  <transmission name="trans_LBR3R760iisy_Urdf_Joint1_name">
    <actuator name="LBR3R760iisy_Urdf_Joint1_name_motor">
      <hardwareInterface>EffortJointInterface</hardwareInterface>
      <mechanicalReduction>1.0</mechanicalReduction>
    </actuator>
    <joint name="Joint1">
      <hardwareInterface>hardware_interface/EffortJointInterface</hardwareInterface>
    </joint>
    <type>transmission_interface/SimpleTransmission</type>
  </transmission>
  <link name="base_link"/>
</robot>